Workbook
Name Slicer_Category: #N/A
Name Slicer_Gender: #N/A
Name Slicer_Region: #N/A
Name Slicer_Store_Type: #N/A

Sheet Customer_Dim
A1: Customer_ID | B1: Name | C1: Age | D1: Gender | E1: City | F1: State | G1: Country | H1: Loyalty_Level
A2: CUST1000 | B2: Sheena Bonilla | C2: 55 | D2: Male | E2: Donaldton | F2: North Carolina | G2: USA | H2: Platinum
A3: CUST1001 | B3: Eugene Nelson | C3: 26 | D3: Female | E3: Phillipsmouth | F3: North Dakota | G3: USA | H3: Platinum
A4: CUST1002 | B4: Dr. Benjamin Price | C4: 29 | D4: Female | E4: Kylebury | F4: Alabama | G4: USA | H4: Platinum
A5: CUST1003 | B5: Jeremy Harris | C5: 59 | D5: Female | E5: Thomastown | F5: Ohio | G5: USA | H5: Bronze
A6: CUST1004 | B6: Caroline Collins | C6: 64 | D6: Female | E6: Nicholasshire | F6: California | G6: USA | H6: Silver
A7: CUST1005 | B7: Christine Vaughn | C7: 24 | D7: Male | E7: East Amandamouth | F7: Oregon | G7: USA | H7: Bronze
A8: CUST1006 | B8: Amber Jackson | C8: 29 | D8: Female | E8: Deborahborough | F8: South Dakota | G8: USA | H8: Platinum
A9: CUST1007 | B9: Daniel Boyd | C9: 29 | D9: Female | E9: West Pamelafurt | F9: West Virginia | G9: USA | H9: Bronze
A10: CUST1008 | B10: Melissa Howard | C10: 53 | D10: Female | E10: Maynardton | F10: New Hampshire | G10: USA | H10: Gold
A11: CUST1009 | B11: Ms. Maria Leach | C11: 64 | D11: Male | E11: Melissashire | F11: Pennsylvania | G11: USA | H11: Platinum
A12: CUST1010 | B12: Dominic Page | C12: 53 | D12: Male | E12: Port Michaelburgh | F12: Pennsylvania | G12: USA | H12: Bronze
A13: CUST1011 | B13: Brian Lopez | C13: 28 | D13: Female | E13: East Krista | F13: New York | G13: USA | H13: Gold
... A501: CUST1499 | B501: Philip Pennington | C501: 27 | D501: Female | E501: East Valerieview | F501: Oregon | G501: USA | H501: Platinum

Sheet Product_Dim
A1: Product_ID | B1: Product_Name | C1: Category | D1: Sub_Category | E1: Brand | F1: Cost | G1: Stock
A2: PROD0 | B2: Brother Laser Printer | C2: Electronics | D2: Computer | E2: Hunt Inc | F2: 112.42 | G2: 416
A3: PROD1 | B3: Men's Graphic T-Shirt | C3: Clothing | D3: Tops | E3: Terry-Moore | F3: 342.56 | G3: 181
A4: PROD2 | B4: Women's Casual Hoodie | C4: Clothing | D4: Outerwear | E4: Sims Inc | F4: 296.83 | G4: 352
A5: PROD3 | B5: Men's Running Jacket | C5: Clothing | D5: Outerwear | E5: Pineda Ltd | F5: 364.67 | G5: 452
A6: PROD4 | B6: Women's Yoga Pants | C6: Clothing | D6: Bottoms | E6: Gonzales-Davis | F6: 306.46 | G6: 487
A7: PROD5 | B7: Men's Leather Belt | C7: Clothing | D7: Accessories | E7: Baldwin, Garza and Gonzalez | F7: 261 | G7: 59
A8: PROD6 | B8: Herbal Face Moisturizer | C8: Beauty | D8: Skincare | E8: Davidson PLC | F8: 312.8 | G8: 350
A9: PROD7 | B9: LED Table Lamp | C9: Home | D9: Lighting | E9: Harrell LLC | F9: 218.86 | G9: 170
A10: PROD8 | B10: Wireless Bluetooth Earbuds | C10: Electronics | D10: Audio | E10: Perez-Johnston | F10: 439.07 | G10: 142
A11: PROD9 | B11: Adjustable Dumbbell Set | C11: Sports | D11: Fitness | E11: Hill PLC | F11: 495.72 | G11: 323
A12: PROD10 | B12: Ceramic Kitchen Bowl Set | C12: Home | D12: Kitchen | E12: Hamilton Group | F12: 298.86 | G12: 308
A13: PROD11 | B13: HD Smart TV Stick | C13: Electronics | D13: Accessories | E13: Gibson, Hobbs and Weaver | F13: 449.4 | G13: 338
... A101: PROD99 | B101: Stainless Steel Cookware Set | C101: Home | D101: Kitchen | E101: Campbell Ltd | F101: 201.41 | G101: 146

Sheet Store_Dim
A1: Store_ID | B1: Store_Name | C1: Region | D1: City | E1: Store_Type
A2: STORE0 | B2: Rivera-Warner | C2: East | D2: Washingtonfurt | E2: Flagship
A3: STORE1 | B3: Martinez, Adkins and Johnson | C3: North | D3: Danielmouth | E3: Flagship
A4: STORE2 | B4: Black-Horn | C4: South | D4: North Nancyview | E4: Outlet
A5: STORE3 | B5: Johnson-Wright | C5: North | D5: Hoodberg | E5: Outlet
A6: STORE4 | B6: Alexander Group | C6: South | D6: Port Sharon | E6: Online
A7: STORE5 | B7: Gray Ltd | C7: North | D7: New Michaelchester | E7: Outlet
A8: STORE6 | B8: Benson-Elliott | C8: East | D8: Port Josephberg | E8: Online
A9: STORE7 | B9: Martinez-Mullins | C9: South | D9: Williamsfurt | E9: Online
A10: STORE8 | B10: Bean, Jones and Park | C10: West | D10: Thompsonborough | E10: Online
A11: STORE9 | B11: Moore, Padilla and Butler | C11: South | D11: East Johnstad | E11: Flagship
A12: STORE10 | B12: Hill, Wagner and Ballard | C12: East | D12: East Davidville | E12: Online
... A21: STORE19 | B21: Mann-Austin | C21: East | D21: Vasquezborough | E21: Online
G29: Column1

Sheet Sales_Fact
A1: Sales_ID | B1: Order_Date | C1: Customer_ID | D1: Product_ID | E1: Store_ID | F1: Quantity | G1: Unit_Price | H1: Discount | I1: Payment_Type | J1: Total_Amount
A2: SALE0 | B2: 45480 | C2: CUST1409 | D2: PROD97 | E2: STORE3 | F2: 1 | G2: 218.04 | H2: 0.09 | I2: Credit Card | J2: 198.4164
A3: SALE1 | B3: 45285 | C3: CUST1467 | D3: PROD74 | E3: STORE17 | F3: 3 | G3: 104.47 | H3: 0.27 | I3: PayPal | J3: 228.7893
A4: SALE2 | B4: 45446 | C4: CUST1056 | D4: PROD49 | E4: STORE8 | F4: 4 | G4: 914.05 | H4: 0.25 | I4: Credit Card | J4: 2742.15
A5: SALE3 | B5: 45259 | C5: CUST1346 | D5: PROD76 | E5: STORE8 | F5: 1 | G5: 921.51 | H5: 0.16 | I5: COD | J5: 774.0684
A6: SALE4 | B6: 45297 | C6: CUST1493 | D6: PROD59 | E6: STORE5 | F6: 3 | G6: 745.3 | H6: 0.18 | I6: Credit Card | J6: 1833.438
A7: SALE5 | B7: 45499 | C7: CUST1116 | D7: PROD15 | E7: STORE7 | F7: 3 | G7: 147.01 | H7: 0.19 | I7: COD | J7: 357.2343
A8: SALE6 | B8: 45850 | C8: CUST1016 | D8: PROD56 | E8: STORE4 | F8: 2 | G8: 785.31 | H8: 0.15 | I8: PayPal | J8: 1335.027
A9: SALE7 | B9: 45248 | C9: CUST1152 | D9: PROD70 | E9: STORE8 | F9: 4 | G9: 342.39 | H9: 0.23 | I9: PayPal | J9: 1054.5612
A10: SALE8 | B10: 45781 | C10: CUST1187 | D10: PROD99 | E10: STORE5 | F10: 2 | G10: 448.25 | H10: 0.07 | I10: PayPal | J10: 1250.6175
A11: SALE9 | B11: 45869 | C11: CUST1464 | D11: PROD33 | E11: STORE0 | F11: 2 | G11: 873.17 | H11: 0.23 | I11: PayPal | J11: 1344.6818
A12: SALE10 | B12: 45335 | C12: CUST1065 | D12: PROD24 | E12: STORE14 | F12: 1 | G12: 278.63 | H12: 0.07 | I12: Credit Card | J12: 259.1259
A13: SALE11 | B13: 45801 | C13: CUST1320 | D13: PROD39 | E13: STORE1 | F13: 4 | G13: 286.92 | H13: 0.17 | I13: Credit Card | J13: 952.5744
... A65: SALE63 | B65: 45927 | C65: CUST1126 | D65: PROD89 | E65: STORE12 | F65: 2 | G65: 121.37 | H65: 0.05 | I65: Credit Card | J65: 230.603
A66: SALE64 | B66: 45914 | C66: CUST1255 | D66: PROD53 | E66: STORE10 | F66: 3 | G66: 480.06 | H66: 0.01 | I66: Credit Card | J66: =Table6[[#This Row],[Quantity]]*Table6[[#This Row],[Unit_Price]] -> 1440.18
A67: SALE65 | B67: 45290 | C67: CUST1162 | D67: PROD99 | E67: STORE17 | F67: 2 | G67: 856.57 | H67: 0.24 | I67: Credit Card | J67: 1301.9864
A68: SALE66 | B68: 45213 | C68: CUST1269 | D68: PROD77 | E68: STORE2 | F68: 4 | G68: 814.25 | H68: 0.18 | I68: Credit Card | J68: 2670.74
A69: SALE67 | B69: 45255 | C69: CUST1483 | D69: PROD12 | E69: STORE2 | F69: 1 | G69: 989.17 | H69: 0.2 | I69: PayPal | J69: 791.336
A70: SALE68 | B70: 45270 | C70: CUST1372 | D70: PROD72 | E70: STORE10 | F70: 4 | G70: 62.48 | H70: 0.18 | I70: Credit Card | J70: 204.9344
A71: SALE69 | B71: 45897 | C71: CUST1423 | D71: PROD13 | E71: STORE16 | F71: 4 | G71: 561.24 | H71: 0.24 | I71: Credit Card | J71: 1706.1696
A72: SALE70 | B72: 45849 | C72: CUST1058 | D72: PROD60 | E72: STORE5 | F72: 3 | G72: 92.24 | H72: 0.28 | I72: COD | J72: =Table6[[#This Row],[Quantity]]*Table6[[#This Row],[Unit_Price]] -> 276.72
A73: SALE71 | B73: 45889 | C73: CUST1168 | D73: PROD72 | E73: STORE1 | F73: 2 | G73: 668.3 | H73: 0.07 | I73: Credit Card | J73: 1243.038
A74: SALE72 | B74: 45533 | C74: CUST1409 | D74: PROD38 | E74: STORE5 | F74: 1 | G74: 553.82 | H74: 0.09 | I74: Credit Card | J74: 503.9762
A75: SALE73 | B75: 45626 | C75: CUST1037 | D75: PROD45 | E75: STORE11 | F75: 2 | G75: 556.43 | H75: 0.13 | I75: Credit Card | J75: 968.1882
A76: SALE74 | B76: 45942 | C76: CUST1273 | D76: PROD20 | E76: STORE8 | F76: 1 | G76: 184.98 | H76: 0.1 | I76: COD | J76: 166.482
A77: SALE75 | B77: 45500 | C77: CUST1035 | D77: PROD97 | E77: STORE12 | F77: 4 | G77: 700.18 | H77: 0.23 | I77: Credit Card | J77: 2156.5544
A78: SALE76 | B78: 45285 | C78: CUST1019 | D78: PROD76 | E78: STORE10 | F78: 2 | G78: 686.31 | H78: 0.25 | I78: Credit Card | J78: 1029.465
A79: SALE77 | B79: 45800 | C79: CUST1007 | D79: PROD67 | E79: STORE15 | F79: 1 | G79: 687.82 | H79: 0.27 | I79: COD | J79: 502.1086
A80: SALE78 | B80: 45609 | C80: CUST1221 | D80: PROD83 | E80: STORE8 | F80: 2 | G80: 900.55 | H80: 0.16 | I80: Credit Card | J80: 1512.924
A81: SALE79 | B81: 45268 | C81: CUST1115 | D81: PROD21 | E81: STORE2 | F81: 1 | G81: 341.17 | H81: 0.15 | I81: Credit Card | J81: 289.9945
A82: SALE80 | B82: 45885 | C82: CUST1176 | D82: PROD52 | E82: STORE8 | F82: 1 | G82: 442.27 | H82: 0.06 | I82: COD | J82: 415.7338
A83: SALE81 | B83: 45616 | C83: CUST1253 | D83: PROD71 | E83: STORE9 | F83: 1 | G83: 363.73 | H83: 0.25 | I83: PayPal | J83: 272.7975
A84: SALE82 | B84: 45518 | C84: CUST1378 | D84: PROD91 | E84: STORE17 | F84: 2 | G84: 601.33 | H84: 0.16 | I84: PayPal | J84: 1010.2344
A85: SALE83 | B85: 45427 | C85: CUST1403 | D85: PROD17 | E85: STORE18 | F85: 4 | G85: 34.39 | H85: 0.03 | I85: PayPal | J85: 133.4332
A86: SALE84 | B86: 45268 | C86: CUST1423 | D86: PROD46 | E86: STORE17 | F86: 1 | G86: 773.57 | H86: 0.05 | I86: COD | J86: =Table6[[#This Row],[Quantity]]*Table6[[#This Row],[Unit_Price]] -> 773.57
A87: SALE85 | B87: 45282 | C87: CUST1054 | D87: PROD88 | E87: STORE7 | F87: 4 | G87: 127.1 | H87: 0.24 | I87: COD | J87: 386.384
A88: SALE86 | B88: 45545 | C88: CUST1303 | D88: PROD20 | E88: STORE3 | F88: 3 | G88: 899.58 | H88: 0.28 | I88: PayPal | J88: 1943.0928
A89: SALE87 | B89: 45755 | C89: CUST1327 | D89: PROD1 | E89: STORE10 | F89: 3 | G89: 964.39 | H89: 0.04 | I89: Credit Card | J89: 2777.4432
A90: SALE88 | B90: 45588 | C90: CUST1183 | D90: PROD38 | E90: STORE0 | F90: 2 | G90: 217.83 | H90: 0.14 | I90: PayPal | J90: 374.6676
A91: SALE89 | B91: 45848 | C91: CUST1143 | D91: PROD17 | E91: STORE1 | F91: 4 | G91: 187.71 | H91: 0.06 | I91: COD | J91: 705.7896
...

Sheet Ecommerce Combined Data
A1: Customer ID | B1: Store ID | C1: Product ID | D1: Name | E1: Age | F1: Gender | G1: City | H1: State | I1: Loyalty Level | J1: Product Name | K1: Category | L1: Sub Category | M1: Brand | N1: Cost | O1: Stock | P1: Store Name | Q1: Region | R1: Store Type | S1: Total Amount
A2: CUST1000 | B2: =_xlfn.XLOOKUP(Table7[[#This Row],[Customer ID]],Table6[Customer_ID],Table6[Store_ID]) -> STORE16 | C2: =_xlfn.XLOOKUP(Table7[[#This Row],[Customer ID]],Table6[Customer_ID],Table6[Product_ID]) -> PROD63 | D2: =VLOOKUP(Table7[[#This Row],[Customer ID]],Table4[#All],2,FALSE) -> Sheena Bonilla | E2: =VLOOKUP($A2,Table4[],3,FALSE) -> 55 | F2: =VLOOKUP($A2,Table4[],4,FALSE) -> Male | G2: =VLOOKUP($A2,Table4[],5,FALSE) -> Donaldton | H2: =VLOOKUP($A2,Table4[],6,FALSE) -> North Carolina | I2: =VLOOKUP($A2,Table4[],8,FALSE) -> Platinum | J2: =VLOOKUP($C2,Table1[],2,FALSE) -> Organic Sunscreen Lotion | K2: =VLOOKUP($C2,Table1[],3,FALSE) -> Beauty | L2: =VLOOKUP($C2,Table1[],4,FALSE) -> Skincare | M2: =VLOOKUP($C2,Table1[],5,FALSE) -> Anderson-Riley | N2: =VLOOKUP($C2,Table1[],6,FALSE) -> 266.86 | O2: =VLOOKUP($C2,Table1[],7,FALSE) -> 458 | P2: =_xlfn.XLOOKUP($B2,Table3[Store_ID],Table3[Store_Name]) -> Frederick-Wright | Q2: {=_xlfn.XLOOKUP($B2,Store_Dim!$A$2:$A$21,Table3[Region])} -> West | R2: {=_xlfn.XLOOKUP($B2,Store_Dim!$A$2:$A$21,Table3[Store_Type])} -> Flagship | S2: =VLOOKUP(Table7[[#This Row],[Customer ID]],Table6[[Customer_ID]:[Total_Amount]],8,FALSE) -> 598.239
A3: CUST1001 | B3: =_xlfn.XLOOKUP(Table7[[#This Row],[Customer ID]],Table6[Customer_ID],Table6[Store_ID]) -> STORE14 | C3: =_xlfn.XLOOKUP(Table7[[#This Row],[Customer ID]],Table6[Customer_ID],Table6[Product_ID]) -> PROD51 | D3: =VLOOKUP(Table7[[#This Row],[Customer ID]],Table4[#All],2,FALSE) -> Eugene Nelson | E3: =VLOOKUP($A3,Table4[],3,FALSE) -> 26 | F3: =VLOOKUP($A3,Table4[],4,FALSE) -> Female | G3: =VLOOKUP($A3,Table4[],5,FALSE) -> Phillipsmouth | H3: =VLOOKUP($A3,Table4[],6,FALSE) -> North Dakota | I3: =VLOOKUP($A3,Table4[],8,FALSE) -> Platinum | J3: =VLOOKUP($C3,Table1[],2,FALSE) -> HDMI Cable – 2m | K3: =VLOOKUP($C3,Table1[],3,FALSE) -> Electronics | L3: =VLOOKUP($C3,Table1[],4,FALSE) -> Accessories | M3: =VLOOKUP($C3,Table1[],5,FALSE) -> Bautista, Green and Hale | N3: =VLOOKUP($C3,Table1[],6,FALSE) -> 88.49 | O3: =VLOOKUP($C3,Table1[],7,FALSE) -> 246 | P3: =_xlfn.XLOOKUP($B3,Table3[Store_ID],Table3[Store_Name]) -> Mcdonald Inc | Q3: {=_xlfn.XLOOKUP($B3,Store_Dim!$A$2:$A$21,Table3[Region])} -> South | R3: {=_xlfn.XLOOKUP($B3,Store_Dim!$A$2:$A$21,Table3[Store_Type])} -> Outlet | S3: =VLOOKUP(Table7[[#This Row],[Customer ID]],Table6[[Customer_ID]:[Total_Amount]],8,FALSE) -> 837.2361
A4: CUST1002 | B4: =_xlfn.XLOOKUP(Table7[[#This Row],[Customer ID]],Table6[Customer_ID],Table6[Store_ID]) -> STORE17 | C4: =_xlfn.XLOOKUP(Table7[[#This Row],[Customer ID]],Table6[Customer_ID],Table6[Product_ID]) -> PROD79 | D4: =VLOOKUP(Table7[[#This Row],[Customer ID]],Table4[#All],2,FALSE) -> Dr. Benjamin Price | E4: =VLOOKUP($A4,Table4[],3,FALSE) -> 29 | F4: =VLOOKUP($A4,Table4[],4,FALSE) -> Female | G4: =VLOOKUP($A4,Table4[],5,FALSE) -> Kylebury | H4: =VLOOKUP($A4,Table4[],6,FALSE) -> Alabama | I4: =VLOOKUP($A4,Table4[],8,FALSE) -> Platinum | J4: =VLOOKUP($C4,Table1[],2,FALSE) -> Decorative Lamp Shade | K4: =VLOOKUP($C4,Table1[],3,FALSE) -> Home | L4: =VLOOKUP($C4,Table1[],4,FALSE) -> Lighting | M4: =VLOOKUP($C4,Table1[],5,FALSE) -> Ramirez-Hanson | N4: =VLOOKUP($C4,Table1[],6,FALSE) -> 228.53 | O4: =VLOOKUP($C4,Table1[],7,FALSE) -> 469 | P4: =_xlfn.XLOOKUP($B4,Table3[Store_ID],Table3[Store_Name]) -> Holloway Ltd | Q4: {=_xlfn.XLOOKUP($B4,Store_Dim!$A$2:$A$21,Table3[Region])} -> North | R4: {=_xlfn.XLOOKUP($B4,Store_Dim!$A$2:$A$21,Table3[Store_Type])} -> Flagship | S4: =VLOOKUP(Table7[[#This Row],[Customer ID]],Table6[[Customer_ID]:[Total_Amount]],8,FALSE) -> 602.2512
A5: CUST1003 | B5: =_xlfn.XLOOKUP(Table7[[#This Row],[Customer ID]],Table6[Customer_ID],Table6[Store_ID]) -> STORE14 | C5: =_xlfn.XLOOKUP(Table7[[#This Row],[Customer ID]],Table6[Customer_ID],Table6[Product_ID]) -> PROD0 | D5: =VLOOKUP(Table7[[#This Row],[Customer ID]],Table4[#All],2,FALSE) -> Jeremy Harris | E5: =VLOOKUP($A5,Table4[],3,FALSE) -> 59 | F5: =VLOOKUP($A5,Table4[],4,FALSE) -> Female | G5: =VLOOKUP($A5,Table4[],5,FALSE) -> Thomastown | H5: =VLOOKUP($A5,Table4[],6,FALSE) -> Ohio | I5: =VLOOKUP($A5,Table4[],8,FALSE) -> Bronze | J5: =VLOOKUP($C5,Table1[],2,FALSE) -> Brother Laser Printer | K5: =VLOOKUP($C5,Table1[],3,FALSE) -> Electronics | L5: =VLOOKUP($C5,Table1[],4,FALSE) -> Computer | M5: =VLOOKUP($C5,Table1[],5,FALSE) -> Hunt Inc | N5: =VLOOKUP($C5,Table1[],6,FALSE) -> 112.42 | O5: =VLOOKUP($C5,Table1[],7,FALSE) -> 416 | P5: =_xlfn.XLOOKUP($B5,Table3[Store_ID],Table3[Store_Name]) -> Mcdonald Inc | Q5: {=_xlfn.XLOOKUP($B5,Store_Dim!$A$2:$A$21,Table3[Region])} -> South | R5: {=_xlfn.XLOOKUP($B5,Store_Dim!$A$2:$A$21,Table3[Store_Type])} -> Outlet | S5: =VLOOKUP(Table7[[#This Row],[Customer ID]],Table6[[Customer_ID]:[Total_Amount]],8,FALSE) -> 445.104
A6: CUST1004 | B6: =_xlfn.XLOOKUP(Table7[[#This Row],[Customer ID]],Table6[Customer_ID],Table6[Store_ID]) -> STORE17 | C6: =_xlfn.XLOOKUP(Table7[[#This Row],[Customer ID]],Table6[Customer_ID],Table6[Product_ID]) -> PROD47 | D6: =VLOOKUP(Table7[[#This Row],[Customer ID]],Table4[#All],2,FALSE) -> Caroline Collins | E6: =VLOOKUP($A6,Table4[],3,FALSE) -> 64 | F6: =VLOOKUP($A6,Table4[],4,FALSE) -> Female | G6: =VLOOKUP($A6,Table4[],5,FALSE) -> Nicholasshire | H6: =VLOOKUP($A6,Table4[],6,FALSE) -> California | I6: =VLOOKUP($A6,Table4[],8,FALSE) -> Silver | J6: =VLOOKUP($C6,Table1[],2,FALSE) -> Makeup Brush Set | K6: =VLOOKUP($C6,Table1[],3,FALSE) -> Beauty | L6: =VLOOKUP($C6,Table1[],4,FALSE) -> Makeup | M6: =VLOOKUP($C6,Table1[],5,FALSE) -> Cook Inc | N6: =VLOOKUP($C6,Table1[],6,FALSE) -> 241.07 | O6: =VLOOKUP($C6,Table1[],7,FALSE) -> 431 | P6: =_xlfn.XLOOKUP($B6,Table3[Store_ID],Table3[Store_Name]) -> Holloway Ltd | Q6: {=_xlfn.XLOOKUP($B6,Store_Dim!$A$2:$A$21,Table3[Region])} -> North | R6: {=_xlfn.XLOOKUP($B6,Store_Dim!$A$2:$A$21,Table3[Store_Type])} -> Flagship | S6: =VLOOKUP(Table7[[#This Row],[Customer ID]],Table6[[Customer_ID]:[Total_Amount]],8,FALSE) -> 476.9166
A7: CUST1005 | B7: =_xlfn.XLOOKUP(Table7[[#This Row],[Customer ID]],Table6[Customer_ID],Table6[Store_ID]) -> STORE12 | C7: =_xlfn.XLOOKUP(Table7[[#This Row],[Customer ID]],Table6[Customer_ID],Table6[Product_ID]) -> PROD61 | D7: =VLOOKUP(Table7[[#This Row],[Customer ID]],Table4[#All],2,FALSE) -> Christine Vaughn | E7: =VLOOKUP($A7,Table4[],3,FALSE) -> 24 | F7: =VLOOKUP($A7,Table4[],4,FALSE) -> Male | G7: =VLOOKUP($A7,Table4[],5,FALSE) -> East Amandamouth | H7: =VLOOKUP($A7,Table4[],6,FALSE) -> Oregon | I7: =VLOOKUP($A7,Table4[],8,FALSE) -> Bronze | J7: =VLOOKUP($C7,Table1[],2,FALSE) -> Tennis Ball 3-Pack | K7: =VLOOKUP($C7,Table1[],3,FALSE) -> Sports | L7: =VLOOKUP($C7,Table1[],4,FALSE) -> Equipment | M7: =VLOOKUP($C7,Table1[],5,FALSE) -> Lopez LLC | N7: =VLOOKUP($C7,Table1[],6,FALSE) -> 103.45 | O7: =VLOOKUP($C7,Table1[],7,FALSE) -> 465 | P7: =_xlfn.XLOOKUP($B7,Table3[Store_ID],Table3[Store_Name]) -> Thomas, Bridges and Harris | Q7: {=_xlfn.XLOOKUP($B7,Store_Dim!$A$2:$A$21,Table3[Region])} -> North | R7: {=_xlfn.XLOOKUP($B7,Store_Dim!$A$2:$A$21,Table3[Store_Type])} -> Online | S7: =VLOOKUP(Table7[[#This Row],[Customer ID]],Table6[[Customer_ID]:[Total_Amount]],8,FALSE) -> 2574.9856
A8: CUST1006 | B8: =_xlfn.XLOOKUP(Table7[[#This Row],[Customer ID]],Table6[Customer_ID],Table6[Store_ID]) -> STORE4 | C8: =_xlfn.XLOOKUP(Table7[[#This Row],[Customer ID]],Table6[Customer_ID],Table6[Product_ID]) -> PROD93 | D8: =VLOOKUP(Table7[[#This Row],[Customer ID]],Table4[#All],2,FALSE) -> Amber Jackson | E8: =VLOOKUP($A8,Table4[],3,FALSE) -> 29 | F8: =VLOOKUP($A8,Table4[],4,FALSE) -> Female | G8: =VLOOKUP($A8,Table4[],5,FALSE) -> Deborahborough | H8: =VLOOKUP($A8,Table4[],6,FALSE) -> South Dakota | I8: =VLOOKUP($A8,Table4[],8,FALSE) -> Platinum | J8: =VLOOKUP($C8,Table1[],2,FALSE) -> USB-C Laptop Charger | K8: =VLOOKUP($C8,Table1[],3,FALSE) -> Electronics | L8: =VLOOKUP($C8,Table1[],4,FALSE) -> Computer | M8: =VLOOKUP($C8,Table1[],5,FALSE) -> Martin LLC | N8: =VLOOKUP($C8,Table1[],6,FALSE) -> 377.52 | O8: =VLOOKUP($C8,Table1[],7,FALSE) -> 485 | P8: =_xlfn.XLOOKUP($B8,Table3[Store_ID],Table3[Store_Name]) -> Alexander Group | Q8: {=_xlfn.XLOOKUP($B8,Store_Dim!$A$2:$A$21,Table3[Region])} -> South | R8: {=_xlfn.XLOOKUP($B8,Store_Dim!$A$2:$A$21,Table3[Store_Type])} -> Online | S8: =VLOOKUP(Table7[[#This Row],[Customer ID]],Table6[[Customer_ID]:[Total_Amount]],8,FALSE) -> 1204.6944
A9: CUST1007 | B9: =_xlfn.XLOOKUP(Table7[[#This Row],[Customer ID]],Table6[Customer_ID],Table6[Store_ID]) -> STORE15 | C9: =_xlfn.XLOOKUP(Table7[[#This Row],[Customer ID]],Table6[Customer_ID],Table6[Product_ID]) -> PROD67 | D9: =VLOOKUP(Table7[[#This Row],[Customer ID]],Table4[#All],2,FALSE) -> Daniel Boyd | E9: =VLOOKUP($A9,Table4[],3,FALSE) -> 29 | F9: =VLOOKUP($A9,Table4[],4,FALSE) -> Female | G9: =VLOOKUP($A9,Table4[],5,FALSE) -> West Pamelafurt | H9: =VLOOKUP($A9,Table4[],6,FALSE) -> West Virginia | I9: =VLOOKUP($A9,Table4[],8,FALSE) -> Bronze | J9: =VLOOKUP($C9,Table1[],2,FALSE) -> Smart LED Light Strip | K9: =VLOOKUP($C9,Table1[],3,FALSE) -> Electronics | L9: =VLOOKUP($C9,Table1[],4,FALSE) -> Accessories | M9: =VLOOKUP($C9,Table1[],5,FALSE) -> Flores-Davis | N9: =VLOOKUP($C9,Table1[],6,FALSE) -> 349.17 | O9: =VLOOKUP($C9,Table1[],7,FALSE) -> 476 | P9: =_xlfn.XLOOKUP($B9,Table3[Store_ID],Table3[Store_Name]) -> Shelton PLC | Q9: {=_xlfn.XLOOKUP($B9,Store_Dim!$A$2:$A$21,Table3[Region])} -> North | R9: {=_xlfn.XLOOKUP($B9,Store_Dim!$A$2:$A$21,Table3[Store_Type])} -> Flagship | S9: =VLOOKUP(Table7[[#This Row],[Customer ID]],Table6[[Customer_ID]:[Total_Amount]],8,FALSE) -> 502.1086
A10: CUST1008 | B10: =_xlfn.XLOOKUP(Table7[[#This Row],[Customer ID]],Table6[Customer_ID],Table6[Store_ID]) -> STORE11 | C10: =_xlfn.XLOOKUP(Table7[[#This Row],[Customer ID]],Table6[Customer_ID],Table6[Product_ID]) -> PROD30 | D10: =VLOOKUP(Table7[[#This Row],[Customer ID]],Table4[#All],2,FALSE) -> Melissa Howard | E10: =VLOOKUP($A10,Table4[],3,FALSE) -> 53 | F10: =VLOOKUP($A10,Table4[],4,FALSE) -> Female | G10: =VLOOKUP($A10,Table4[],5,FALSE) -> Maynardton | H10: =VLOOKUP($A10,Table4[],6,FALSE) -> New Hampshire | I10: =VLOOKUP($A10,Table4[],8,FALSE) -> Gold | J10: =VLOOKUP($C10,Table1[],2,FALSE) -> Stainless Steel Cutlery Set | K10: =VLOOKUP($C10,Table1[],3,FALSE) -> Home | L10: =VLOOKUP($C10,Table1[],4,FALSE) -> Kitchen | M10: =VLOOKUP($C10,Table1[],5,FALSE) -> Stevens, Fernandez and Martin | N10: =VLOOKUP($C10,Table1[],6,FALSE) -> 19.52 | O10: =VLOOKUP($C10,Table1[],7,FALSE) -> 57 | P10: =_xlfn.XLOOKUP($B10,Table3[Store_ID],Table3[Store_Name]) -> Aguirre-Keller | Q10: {=_xlfn.XLOOKUP($B10,Store_Dim!$A$2:$A$21,Table3[Region])} -> South | R10: {=_xlfn.XLOOKUP($B10,Store_Dim!$A$2:$A$21,Table3[Store_Type])} -> Online | S10: =VLOOKUP(Table7[[#This Row],[Customer ID]],Table6[[Customer_ID]:[Total_Amount]],8,FALSE) -> 116.7708
A11: CUST1009 | B11: =_xlfn.XLOOKUP(Table7[[#This Row],[Customer ID]],Table6[Customer_ID],Table6[Store_ID]) -> STORE13 | C11: =_xlfn.XLOOKUP(Table7[[#This Row],[Customer ID]],Table6[Customer_ID],Table6[Product_ID]) -> PROD78 | D11: =VLOOKUP(Table7[[#This Row],[Customer ID]],Table4[#All],2,FALSE) -> Ms. Maria Leach | E11: =VLOOKUP($A11,Table4[],3,FALSE) -> 64 | F11: =VLOOKUP($A11,Table4[],4,FALSE) -> Male | G11: =VLOOKUP($A11,Table4[],5,FALSE) -> Melissashire | H11: =VLOOKUP($A11,Table4[],6,FALSE) -> Pennsylvania | I11: =VLOOKUP($A11,Table4[],8,FALSE) -> Platinum | J11: =VLOOKUP($C11,Table1[],2,FALSE) -> Essential Oil Diffuser | K11: =VLOOKUP($C11,Table1[],3,FALSE) -> Home | L11: =VLOOKUP($C11,Table1[],4,FALSE) -> Decor | M11: =VLOOKUP($C11,Table1[],5,FALSE) -> Hernandez Inc | N11: =VLOOKUP($C11,Table1[],6,FALSE) -> 325.26 | O11: =VLOOKUP($C11,Table1[],7,FALSE) -> 400 | P11: =_xlfn.XLOOKUP($B11,Table3[Store_ID],Table3[Store_Name]) -> Gardner, Humphrey and Contreras | Q11: {=_xlfn.XLOOKUP($B11,Store_Dim!$A$2:$A$21,Table3[Region])} -> East | R11: {=_xlfn.XLOOKUP($B11,Store_Dim!$A$2:$A$21,Table3[Store_Type])} -> Flagship | S11: =VLOOKUP(Table7[[#This Row],[Customer ID]],Table6[[Customer_ID]:[Total_Amount]],8,FALSE) -> 1173.508
A12: CUST1010 | B12: =_xlfn.XLOOKUP(Table7[[#This Row],[Customer ID]],Table6[Customer_ID],Table6[Store_ID]) -> STORE18 | C12: =_xlfn.XLOOKUP(Table7[[#This Row],[Customer ID]],Table6[Customer_ID],Table6[Product_ID]) -> PROD33 | D12: =VLOOKUP(Table7[[#This Row],[Customer ID]],Table4[#All],2,FALSE) -> Dominic Page | E12: =VLOOKUP($A12,Table4[],3,FALSE) -> 53 | F12: =VLOOKUP($A12,Table4[],4,FALSE) -> Male | G12: =VLOOKUP($A12,Table4[],5,FALSE) -> Port Michaelburgh | H12: =VLOOKUP($A12,Table4[],6,FALSE) -> Pennsylvania | I12: =VLOOKUP($A12,Table4[],8,FALSE) -> Bronze | J12: =VLOOKUP($C12,Table1[],2,FALSE) -> Modern Wall Clock | K12: =VLOOKUP($C12,Table1[],3,FALSE) -> Home | L12: =VLOOKUP($C12,Table1[],4,FALSE) -> Decor | M12: =VLOOKUP($C12,Table1[],5,FALSE) -> Weiss-Watson | N12: =VLOOKUP($C12,Table1[],6,FALSE) -> 179.77 | O12: =VLOOKUP($C12,Table1[],7,FALSE) -> 305 | P12: =_xlfn.XLOOKUP($B12,Table3[Store_ID],Table3[Store_Name]) -> Guerrero-Schmitt | Q12: {=_xlfn.XLOOKUP($B12,Store_Dim!$A$2:$A$21,Table3[Region])} -> East | R12: {=_xlfn.XLOOKUP($B12,Store_Dim!$A$2:$A$21,Table3[Store_Type])} -> Flagship | S12: =VLOOKUP(Table7[[#This Row],[Customer ID]],Table6[[Customer_ID]:[Total_Amount]],8,FALSE) -> 616.2112
A13: CUST1011 | B13: =_xlfn.XLOOKUP(Table7[[#This Row],[Customer ID]],Table6[Customer_ID],Table6[Store_ID]) -> STORE17 | C13: =_xlfn.XLOOKUP(Table7[[#This Row],[Customer ID]],Table6[Customer_ID],Table6[Product_ID]) -> PROD31 | D13: =VLOOKUP(Table7[[#This Row],[Customer ID]],Table4[#All],2,FALSE) -> Brian Lopez | E13: =VLOOKUP($A13,Table4[],3,FALSE) -> 28 | F13: =VLOOKUP($A13,Table4[],4,FALSE) -> Female | G13: =VLOOKUP($A13,Table4[],5,FALSE) -> East Krista | H13: =VLOOKUP($A13,Table4[],6,FALSE) -> New York | I13: =VLOOKUP($A13,Table4[],8,FALSE) -> Gold | J13: =VLOOKUP($C13,Table1[],2,FALSE) -> Basketball | K13: =VLOOKUP($C13,Table1[],3,FALSE) -> Sports | L13: =VLOOKUP($C13,Table1[],4,FALSE) -> Team Sports | M13: =VLOOKUP($C13,Table1[],5,FALSE) -> Nolan-Snow | N13: =VLOOKUP($C13,Table1[],6,FALSE) -> 204.39 | O13: =VLOOKUP($C13,Table1[],7,FALSE) -> 281 | P13: =_xlfn.XLOOKUP($B13,Table3[Store_ID],Table3[Store_Name]) -> Holloway Ltd | Q13: {=_xlfn.XLOOKUP($B13,Store_Dim!$A$2:$A$21,Table3[Region])} -> North | R13: {=_xlfn.XLOOKUP($B13,Store_Dim!$A$2:$A$21,Table3[Store_Type])} -> Flagship | S13: =VLOOKUP(Table7[[#This Row],[Customer ID]],Table6[[Customer_ID]:[Total_Amount]],8,FALSE) -> 560.3795
... A493: CUST1499 | B493: =_xlfn.XLOOKUP(Table7[[#This Row],[Customer ID]],Table6[Customer_ID],Table6[Store_ID]) -> STORE8 | C493: =_xlfn.XLOOKUP(Table7[[#This Row],[Customer ID]],Table6[Customer_ID],Table6[Product_ID]) -> PROD55 | D493: =VLOOKUP(Table7[[#This Row],[Customer ID]],Table4[#All],2,FALSE) -> Philip Pennington | E493: =VLOOKUP($A493,Table4[],3,FALSE) -> 27 | F493: =VLOOKUP($A493,Table4[],4,FALSE) -> Female | G493: =VLOOKUP($A493,Table4[],5,FALSE) -> East Valerieview | H493: =VLOOKUP($A493,Table4[],6,FALSE) -> Oregon | I493: =VLOOKUP($A493,Table4[],8,FALSE) -> Platinum | J493: =VLOOKUP($C493,Table1[],2,FALSE) -> Ceramic Plant Pot | K493: =VLOOKUP($C493,Table1[],3,FALSE) -> Home | L493: =VLOOKUP($C493,Table1[],4,FALSE) -> Decor | M493: =VLOOKUP($C493,Table1[],5,FALSE) -> Hatfield, Baird and Torres | N493: =VLOOKUP($C493,Table1[],6,FALSE) -> 81.75 | O493: =VLOOKUP($C493,Table1[],7,FALSE) -> 331 | P493: =_xlfn.XLOOKUP($B493,Table3[Store_ID],Table3[Store_Name]) -> Bean, Jones and Park | Q493: {=_xlfn.XLOOKUP($B493,Store_Dim!$A$2:$A$21,Table3[Region])} -> West | R493: {=_xlfn.XLOOKUP($B493,Store_Dim!$A$2:$A$21,Table3[Store_Type])} -> Online | S493: =VLOOKUP(Table7[[#This Row],[Customer ID]],Table6[[Customer_ID]:[Total_Amount]],8,FALSE) -> 75.84

Sheet Pivot Table
A3: Category Wise Sales | B3: Sum of Total Amount | D3: Region Wise Average Sales | E3: Average of Total Amount
A4: Beauty | B4: 86661.546 | D4: East | E4: 1099.1092
A5: Clothing | B5: 101680.3 | D5: North | E5: 1166.2792
A6: Electronics | B6: 137388.35 | D6: South | E6: 1232.3763
A7: Home | B7: 92599.533 | D7: West | E7: 1035.3711
A8: Sports | B8: 148806.75 | D8: Grand Total | E8: 1152.7164
A9: Grand Total | B9: 567136.48
A11: Store Type Wise Sales | B11: Sum of Total Amount | D11: Average of Total Amount | E11: Column Labels
A12: Flagship | B12: 183346.91 | D12: Row Labels | E12: Flagship | F12: Online | G12: Outlet | H12: Grand Total
A13: Online | B13: 263401.95 | D13: Female | E13: 1117.34 | F13: 1339.0078 | G13: 1183.8102 | H13: 1232.5316
A14: Outlet | B14: 120387.63 | D14: Male | E14: 1079.5624 | F14: 1029.3051 | G14: 1118.8428 | H14: 1063.9949
A15: Grand Total | B15: 567136.48 | D15: Grand Total | E15: 1097.8857 | F15: 1191.864 | G15: 1157.5734 | H15: 1152.7164
A17: Store Wise Stocks | B17: Sum of Stock
A18: STORE0 | B18: 6661
A19: STORE1 | B19: 5803
A20: STORE10 | B20: 6322
A21: STORE11 | B21: 5758
A22: STORE12 | B22: 8365
A23: STORE13 | B23: 5026
A24: STORE14 | B24: 6661
A25: STORE15 | B25: 6451
A26: STORE16 | B26: 6606
A27: STORE17 | B27: 6893
A28: STORE18 | B28: 5107
A29: STORE19 | B29: 6201
... A38: Grand Total | B38: 138050

Sheet Dashboard
A1: E-Commerce Dashboard
